Workbook

Sheet Sheet1
A1: orders | B1: cp
B2: SU564M5AA
B3: SU564M5PC
B4: SU564M9WN
B5: SU564M9B0
B6: SU564MB82
B7: SU564MANM
B8: SU564M928
B9: SU564V9P4
B10: SU564TRL1
B11: SU564TRLF
B12: SU564TRMT
B13: SU564TRLA
... B21: SU564TN11

Sheet Processed_Logs
A1: timestamp | B1: tracking | C1: orders | D1: bill_no | E1: price | F1: sn | G1: status | H1: error_category | I1: remark
A2: 2026-10-30 09:51:09 | B2: TH265337905744V | C2: 261026N4E3TEE2 | D2: TEST_MODE | E2: 2538.0 | G2: TEST_SUCCESS (ราคาตรงตั้งแต่แรก/All OK) | I2: MNL-002276: POS=2,538.00/เป้า=2,538.00 [ตรง ✅] | Total: POS=2,538.00/เป้า=2,538.00 [ตรง ✅]
A3: 2026-10-30 09:51:32 | B3: TH2689251481250 | C3: 261026N4N7QD7Y | D3: TEST_MODE | E3: 5076.0 | G3: TEST_SUCCESS (ราคาตรงตั้งแต่แรก/All OK) | I3: MNL-002276: POS=2,538.00/เป้า=2,538.00 [ตรง ✅] | Total: POS=5,076.00/เป้า=5,076.00 [ตรง ✅]
A4: 2026-10-30 09:51:32 | B4: TH265767645268Z | C4: 261026N4N7QD7Y | D4: TEST_MODE | E4: 5076.0 | G4: TEST_SUCCESS (ราคาตรงตั้งแต่แรก/All OK) | I4: MNL-002276: POS=2,538.00/เป้า=2,538.00 [ตรง ✅] | Total: POS=5,076.00/เป้า=5,076.00 [ตรง ✅]
A5: 2026-10-30 09:52:41 | B5: TH262826913205C | C5: 261026N59WJ90C | D5: TEST_MODE | E5: 2538.0 | G5: TEST_SUCCESS (ราคาตรงตั้งแต่แรก/All OK) | I5: MNL-002276: POS=2,538.00/เป้า=2,538.00 [ตรง ✅] | Total: POS=2,538.00/เป้า=2,538.00 [ตรง ✅]
A6: 2026-10-30 09:53:04 | B6: TH2669069246018 | C6: 261027NBVJ4BDC | G6: Failed | H6: POSTAL_NOT_FOUND | I6: Postal code 12140 cannot be found in dropdown, auto invoice mode requires postal code selection, stopping the process. Error details: Message: no such element: Unable to locate element: {"method":"xpath","selector":"//li[@role='treeitem' and text()='12140']"} (Session info: chrome=156.0.8078.76); For documentation on this error, please visit: https://www.selenium.dev/documentation/webdriver/troubleshooting/errors#no-such-element-exception Stacktrace: chromedriver!GetHandleVerifier [0x7ff7ae2abe65+4135] chromedriver!(No symbol) [0x7ff7ae1b35f0] chromedriver!(No symbol) [0x7ff7ae0226d3] chromedriver!GetHandleVerifier [0x7ff7ae82d8e1+585bb1] chromedriver!GetHandleVerifier [0x7ff7ae82db3c+585e0c] chromedriver!GetHandleVerifier [0x7ff7ae85bbb7+5b3e87] chromedriver!(No symbol) [0x7ff7ae056661] chromedriver!(No symbol) [0x7ff7ae03b969] chromedriver!(No symbol) [0x7ff7ae03cca3] chromedriver!GetHandleVerifier [0x7ff7ae725af1+47ddc1] chromedriver!GetHandleVerifier [0x7ff7ae7467f7+49eac7] chromedriver!GetHandleVerifier [0x7ff7ae73ce20+4950f0] chromedriver!GetHandleVerifier [0x7ff7ae3cff8e+12825e] chromedriver!(No symbol) [0x7ff7ae1c2865] chromedriver!(No symbol) [0x7ff7ae1bd1d4] chromedriver!(No symbol) [0x7ff7ae1bd364] chromedriver!(No symbol) [0x7ff7ae1a644c] KERNEL32!BaseThreadInitThunk [0x7ffe31ecdda7+17] ntdll!RtlUserThreadStart [0x7ffe3333ee4c+2c] (ด่านที่ติด: ใส่ชื่อลูกค้าสำเร็จ)
A7: 2026-10-30 09:53:30 | B7: TH266513290213Z | C7: 261027PA82YQC9 | D7: TEST_MODE | E7: 5318.0 | G7: TEST_SUCCESS (ปรับราคาและใส่คูปองสำเร็จ/All OK) | I7: MNL-002574: POS=5,318.00/เป้า=5,318.00 [ตรง ✅] | Total: POS=5,318.00/เป้า=5,318.00 [ตรง ✅]
A8: 2026-10-30 09:53:53 | B8: TH2676583686892 | C8: 261027PC9H854G | D8: TEST_MODE | E8: 5894.0 | G8: TEST_SUCCESS (ปรับราคาและใส่คูปองสำเร็จ/All OK) | I8: MNL-002558: POS=5,894.00/เป้า=5,894.00 [ตรง ✅] | Total: POS=5,894.00/เป้า=5,894.00 [ตรง ✅]
A9: 2026-10-30 09:54:14 | B9: TH260434841157A | C9: 261027PCVT9ECQ | D9: TEST_MODE | E9: 2906.0 | G9: TEST_SUCCESS (ราคาตรงตั้งแต่แรก/All OK) | I9: MNL-002445: POS=2,906.00/เป้า=2,906.00 [ตรง ✅] | Total: POS=2,906.00/เป้า=2,906.00 [ตรง ✅]
A10: 2026-10-30 09:54:38 | B10: TH264566352986C | C10: 261027PD2YR6AR | D10: TEST_MODE | E10: 5452.0 | G10: TEST_SUCCESS (ปรับราคาและใส่คูปองสำเร็จ/All OK) | I10: MNL-002574: POS=5,318.00/เป้า=5,318.00 [ตรง ✅] | SV0-000101: POS=134.00/เป้า=134.00 [ตรง ✅] | Total: POS=5,452.00/เป้า=5,452.00 [ตรง ✅]
A11: 2026-10-30 09:55:00 | B11: TH266392709437A | C11: 261027PE90KNSA | D11: TEST_MODE | E11: 5318.0 | G11: TEST_SUCCESS (ปรับราคาและใส่คูปองสำเร็จ/All OK) | I11: MNL-002574: POS=5,318.00/เป้า=5,318.00 [ตรง ✅] | Total: POS=5,318.00/เป้า=5,318.00 [ตรง ✅]
A12: 2026-10-30 09:55:29 | B12: TH265018758621G | C12: 261027PEXVJAFW | G12: ข้าม (สถานะ: ยกเลิกแล้ว)
A13: 2026-10-30 09:55:55 | B13: TH262595631650Y | C13: 261027PFV63DNK | D13: TEST_MODE | E13: 5452.0 | G13: TEST_SUCCESS (ปรับราคาและใส่คูปองสำเร็จ/All OK) | I13: MNL-002574: POS=5,318.00/เป้า=5,318.00 [ตรง ✅] | SV0-000101: POS=134.00/เป้า=134.00 [ตรง ✅] | Total: POS=5,452.00/เป้า=5,452.00 [ตรง ✅]
A14: 2026-10-30 09:56:41 | B14: TH265756486873Z | C14: 261027PG5HFPHY | D14: TEST_MODE | E14: 2065.0 | G14: TEST_SUCCESS (ราคาตรงตั้งแต่แรก/All OK) | I14: MNL-002584: POS=2,065.00/เป้า=2,065.00 [ตรง ✅] | Total: POS=2,065.00/เป้า=2,065.00 [ตรง ✅]
A15: 2026-10-30 09:57:08 | B15: TH2627119261641 | C15: 261027PGJAKV3D | D15: TEST_MODE | E15: 3483.0 | G15: TEST_SUCCESS (ปรับราคาและใส่คูปองสำเร็จ/All OK) | I15: MNL-002326: POS=3,483.00/เป้า=3,483.00 [ตรง ✅] | Total: POS=3,483.00/เป้า=3,483.00 [ตรง ✅]
A16: 2026-10-30 09:57:52 | B16: TH263499323605S | C16: 261027PKB2Q2RH | D16: TEST_MODE | E16: 3525.0 | G16: TEST_SUCCESS (ปรับราคาและใส่คูปองสำเร็จ/All OK) | I16: MNL-002511: POS=3,525.00/เป้า=3,525.00 [ตรง ✅] | Total: POS=3,525.00/เป้า=3,525.00 [ตรง ✅]
A17: 2026-10-30 09:58:36 | B17: TH267791173890D | C17: 261027PNU81KDN | D17: TEST_MODE | E17: 7095.0 | G17: TEST_SUCCESS (ราคาตรงตั้งแต่แรก/All OK) | I17: MNL-002583: POS=7,095.00/เป้า=7,095.00 [ตรง ✅] | Total: POS=7,095.00/เป้า=7,095.00 [ตรง ✅]
A18: 2026-10-30 09:59:06 | B18: TH268247290486S | C18: 261027PQ49A8WK | D18: TEST_MODE | E18: 2529.0 | G18: TEST_SUCCESS (ปรับราคาและใส่คูปองสำเร็จ/All OK) | I18: MNL-002450: POS=2,438.00/เป้า=2,438.00 [ตรง ✅] | SV0-000101: POS=91.00/เป้า=91.00 [ตรง ✅] | Total: POS=2,529.00/เป้า=2,529.00 [ตรง ✅]
A19: 2026-10-30 09:59:35 | B19: TH2660117681305 | C19: 261027PQH938JG | D19: TEST_MODE | E19: 3525.0 | G19: TEST_SUCCESS (ปรับราคาและใส่คูปองสำเร็จ/All OK) | I19: MNL-002511: POS=3,525.00/เป้า=3,525.00 [ตรง ✅] | Total: POS=3,525.00/เป้า=3,525.00 [ตรง ✅]
A20: 2026-10-30 10:00:00 | B20: TH260221242042D | C20: 261027PTCWM3M2 | D20: TEST_MODE | E20: 3483.0 | G20: TEST_SUCCESS (ปรับราคาและใส่คูปองสำเร็จ/All OK) | I20: MNL-002326: POS=3,483.00/เป้า=3,483.00 [ตรง ✅] | Total: POS=3,483.00/เป้า=3,483.00 [ตรง ✅]
A21: 2026-10-30 10:00:23 | B21: TH266253815792A | C21: 261027PTF46M1J | D21: TEST_MODE | E21: 2206.0 | G21: TEST_SUCCESS (ราคาตรงตั้งแต่แรก/All OK) | I21: MNL-002584: POS=2,065.00/เป้า=2,065.00 [ตรง ✅] | SV0-000101: POS=141.00/เป้า=141.00 [ตรง ✅] | Total: POS=2,206.00/เป้า=2,206.00 [ตรง ✅]
A22: 2026-10-30 10:01:06 | B22: TH265223582921R | C22: 261027PVVTDPD1 | D22: TEST_MODE | E22: 3525.0 | G22: TEST_SUCCESS (ปรับราคาและใส่คูปองสำเร็จ/All OK) | I22: MNL-002511: POS=3,525.00/เป้า=3,525.00 [ตรง ✅] | Total: POS=3,525.00/เป้า=3,525.00 [ตรง ✅]
A23: 2026-10-30 10:01:25 | B23: TH266490561779W | C23: 261027PVXX5T2N | D23: TEST_MODE | E23: 2065.0 | G23: TEST_SUCCESS (ราคาตรงตั้งแต่แรก/All OK) | I23: MNL-002584: POS=2,065.00/เป้า=2,065.00 [ตรง ✅] | Total: POS=2,065.00/เป้า=2,065.00 [ตรง ✅]
A24: 2026-10-30 10:01:55 | B24: TH268548202506P | C24: 261027PW3PQ116 | D24: TEST_MODE | E24: 11262.0 | G24: TEST_SUCCESS (ราคาตรงตั้งแต่แรก/All OK) | I24: MNL-002382: POS=11,245.00/เป้า=11,245.00 [ตรง ✅] | SV0-000101: POS=17.00/เป้า=17.00 [ตรง ✅] | Total: POS=11,262.00/เป้า=11,262.00 [ตรง ✅]
... A54: 2026-10-30 10:16:06 | B54: TH260722235943W | C54: 261028RYFXP9WA | D54: TEST_MODE | E54: 3852.0 | G54: TEST_SUCCESS (ปรับราคาและใส่คูปองสำเร็จ/All OK) | I54: MNL-002529: POS=3,797.00/เป้า=3,797.00 [ตรง ✅] | SV0-000101: POS=55.00/เป้า=55.00 [ตรง ✅] | Total: POS=3,852.00/เป้า=3,852.00 [ตรง ✅]
A55: 2026-10-30 10:16:42 | B55: TH263111852620B | C55: 261028S0BSEVF5 | G55: Failed | H55: OTHER | I55: รายการหรือจำนวนสินค้าบน POS ไม่ตรงกับคำสั่งซื้อ: • MNL-002436ไม่จำหน่าย: ไม่พบสินค้านี้บน POS (ลูกค้าสั่ง 1 ชิ้น) (ด่านที่ติด: ตรวจสอบราคาและจำนวนสำเร็จ)
A56: 2026-10-30 10:17:04 | B56: 66857233653558 | C56: 261028S0GBABMP | D56: TEST_MODE | E56: 10986.0 | G56: TEST_SUCCESS (ปรับราคาและใส่คูปองสำเร็จ/All OK) | I56: MNL-002522: POS=5,493.00/เป้า=5,493.00 [ตรง ✅] | Total: POS=10,986.00/เป้า=10,986.00 [ตรง ✅]
A57: 2026-10-30 10:17:04 | B57: 66857236654170 | C57: 261028S0GBABMP | D57: TEST_MODE | E57: 10986.0 | G57: TEST_SUCCESS (ปรับราคาและใส่คูปองสำเร็จ/All OK) | I57: MNL-002522: POS=5,493.00/เป้า=5,493.00 [ตรง ✅] | Total: POS=10,986.00/เป้า=10,986.00 [ตรง ✅]
A58: 2026-10-30 10:17:56 | B58: TH2633005317419 | C58: 261028S0YGS6SE | D58: TEST_MODE | E58: 3039.0 | G58: TEST_SUCCESS (ปรับราคาและใส่คูปองสำเร็จ/All OK) | I58: MNL-002550: POS=3,039.00/เป้า=3,039.00 [ตรง ✅] | Total: POS=3,039.00/เป้า=3,039.00 [ตรง ✅]
A59: 2026-10-30 10:18:20 | B59: TH263456095098S | C59: 261028S162K6F5 | D59: TEST_MODE | E59: 5636.0 | G59: TEST_SUCCESS (ราคาตรงตั้งแต่แรก/All OK) | I59: MNL-002437: POS=5,636.00/เป้า=5,636.00 [ตรง ✅] | Total: POS=5,636.00/เป้า=5,636.00 [ตรง ✅]
A60: 2026-10-30 10:18:49 | B60: TH262342379105B | C60: 261028S21VDBAT | D60: TEST_MODE | E60: 3532.0 | G60: TEST_SUCCESS (ราคาตรงตั้งแต่แรก/All OK) | I60: MNL-002519: POS=3,532.00/เป้า=3,532.00 [ตรง ✅] | Total: POS=3,532.00/เป้า=3,532.00 [ตรง ✅]
A61: 2026-10-30 10:19:08 | B61: 66857235655641 | C61: 261028S26WJDW7 | G61: Failed | H61: OTHER | I61: รายการหรือจำนวนสินค้าบน POS ไม่ตรงกับคำสั่งซื้อ: • MNL-002504ไม่จำหน่าย: ไม่พบสินค้านี้บน POS (ลูกค้าสั่ง 1 ชิ้น) (ด่านที่ติด: ตรวจสอบราคาและจำนวนสำเร็จ)
A62: 2026-10-30 10:20:19 | B62: TH263000203055D | C62: 261028S43YKG8V | D62: TEST_MODE | E62: 2299.0 | G62: TEST_SUCCESS (ราคาตรงตั้งแต่แรก/All OK) | I62: MNL-002507: POS=2,299.00/เป้า=2,299.00 [ตรง ✅] | Total: POS=2,299.00/เป้า=2,299.00 [ตรง ✅]
A63: 2026-10-30 10:20:43 | B63: TH264725598634T | C63: 261028S48DPE3A | D63: TEST_MODE | E63: 3039.0 | G63: TEST_SUCCESS (ปรับราคาและใส่คูปองสำเร็จ/All OK) | I63: MNL-002550: POS=3,039.00/เป้า=3,039.00 [ตรง ✅] | Total: POS=3,039.00/เป้า=3,039.00 [ตรง ✅]
A64: 2026-10-30 10:21:02 | B64: TH01239ACWFS7B | C64: 261028S4BMQ226 | D64: TEST_MODE | E64: 4167.0 | G64: TEST_SUCCESS (ราคาตรงตั้งแต่แรก/All OK) | I64: MNL-002471: POS=4,167.00/เป้า=4,167.00 [ตรง ✅] | Total: POS=4,167.00/เป้า=4,167.00 [ตรง ✅]
A65: 2026-10-30 10:21:27 | B65: TH2671722136436 | C65: 261028S51BWKHW | D65: TEST_MODE | E65: 11632.0 | G65: TEST_SUCCESS (ปรับราคาและใส่คูปองสำเร็จ/All OK) | I65: MNL-002399: POS=11,632.00/เป้า=11,632.00 [ตรง ✅] | Total: POS=11,632.00/เป้า=11,632.00 [ตรง ✅]
A66: 2026-10-30 10:22:37 | B66: TH265938628261G | C66: 261028S5NV12JQ | D66: TEST_MODE | E66: 11632.0 | G66: TEST_SUCCESS (ปรับราคาและใส่คูปองสำเร็จ/All OK) | I66: MNL-002399: POS=11,632.00/เป้า=11,632.00 [ตรง ✅] | Total: POS=11,632.00/เป้า=11,632.00 [ตรง ✅]
A67: 2026-10-30 10:23:24 | B67: TH2670340754221 | C67: 261028S83N5RF1 | D67: TEST_MODE | E67: 3525.0 | G67: TEST_SUCCESS (ปรับราคาและใส่คูปองสำเร็จ/All OK) | I67: MNL-002511: POS=3,525.00/เป้า=3,525.00 [ตรง ✅] | Total: POS=3,525.00/เป้า=3,525.00 [ตรง ✅]
A68: 2026-10-30 10:24:52 | B68: TH2658057273963 | C68: 261028S8S1W90R | D68: TEST_MODE | E68: 4648.0 | G68: TEST_SUCCESS (ปรับราคาและใส่คูปองสำเร็จ/All OK) | I68: MNL-002484: POS=4,648.00/เป้า=4,648.00 [ตรง ✅] | Total: POS=4,648.00/เป้า=4,648.00 [ตรง ✅]
A69: 2026-10-30 10:25:25 | B69: TH269946823739I | C69: 261028S8TGN5MT | D69: TEST_MODE | E69: 3548.0 | G69: TEST_SUCCESS (ราคาตรงตั้งแต่แรก/All OK) | I69: MNL-002498: POS=3,548.00/เป้า=3,548.00 [ตรง ✅] | Total: POS=3,548.00/เป้า=3,548.00 [ตรง ✅]
...

Sheet Completed_Orders
A1: timestamp | B1: orders | C1: status
A2: 2026-10-30 09:51:09 | B2: 261026N4E3TEE2 | C2: TEST_SUCCESS (ราคาตรงตั้งแต่แรก/All OK)
A3: 2026-10-30 09:51:32 | B3: 261026N4N7QD7Y | C3: TEST_SUCCESS (ราคาตรงตั้งแต่แรก/All OK)
A4: 2026-10-30 09:52:41 | B4: 261026N59WJ90C | C4: TEST_SUCCESS (ราคาตรงตั้งแต่แรก/All OK)
A5: 2026-10-30 09:53:30 | B5: 261027PA82YQC9 | C5: TEST_SUCCESS (ปรับราคาและใส่คูปองสำเร็จ/All OK)
A6: 2026-10-30 09:53:53 | B6: 261027PC9H854G | C6: TEST_SUCCESS (ปรับราคาและใส่คูปองสำเร็จ/All OK)
A7: 2026-10-30 09:54:14 | B7: 261027PCVT9ECQ | C7: TEST_SUCCESS (ราคาตรงตั้งแต่แรก/All OK)
A8: 2026-10-30 09:54:38 | B8: 261027PD2YR6AR | C8: TEST_SUCCESS (ปรับราคาและใส่คูปองสำเร็จ/All OK)
A9: 2026-10-30 09:55:00 | B9: 261027PE90KNSA | C9: TEST_SUCCESS (ปรับราคาและใส่คูปองสำเร็จ/All OK)
A10: 2026-10-30 09:55:29 | B10: 261027PEXVJAFW | C10: ข้าม (สถานะ: ยกเลิกแล้ว)
A11: 2026-10-30 09:55:55 | B11: 261027PFV63DNK | C11: TEST_SUCCESS (ปรับราคาและใส่คูปองสำเร็จ/All OK)
A12: 2026-10-30 09:56:41 | B12: 261027PG5HFPHY | C12: TEST_SUCCESS (ราคาตรงตั้งแต่แรก/All OK)
... A302: 2026-10-30 17:41:04 | B302: 261029UMA8HNV7 | C302: TEST_SUCCESS (ปรับราคาและใส่คูปองสำเร็จ/All OK)
A303: 2026-10-30 17:50:32 | B303: 2610300NMFRYE3

Sheet Failed_Orders
A1: timestamp | B1: failed_category | C1: orders | D1: failed_reason
A2: 2026-10-30 09:53:04 | B2: POSTAL_NOT_FOUND | C2: 261027NBVJ4BDC | D2: Postal code 12140 cannot be found in dropdown, auto invoice mode requires postal code selection, stopping the process. Error details: Message: no such element: Unable to locate element: {"method":"xpath","selector":"//li[@role='treeitem' and text()='12140']"} (Session info: chrome=156.0.8078.76); For documentation on this error, please visit: https://www.selenium.dev/documentation/webdriver/troubleshooting/errors#no-such-element-exception Stacktrace: chromedriver!GetHandleVerifier [0x7ff7ae2abe65+4135] chromedriver!(No symbol) [0x7ff7ae1b35f0] chromedriver!(No symbol) [0x7ff7ae0226d3] chromedriver!GetHandleVerifier [0x7ff7ae82d8e1+585bb1] chromedriver!GetHandleVerifier [0x7ff7ae82db3c+585e0c] chromedriver!GetHandleVerifier [0x7ff7ae85bbb7+5b3e87] chromedriver!(No symbol) [0x7ff7ae056661] chromedriver!(No symbol) [0x7ff7ae03b969] chromedriver!(No symbol) [0x7ff7ae03cca3] chromedriver!GetHandleVerifier [0x7ff7ae725af1+47ddc1] chromedriver!GetHandleVerifier [0x7ff7ae7467f7+49eac7] chromedriver!GetHandleVerifier [0x7ff7ae73ce20+4950f0] chromedriver!GetHandleVerifier [0x7ff7ae3cff8e+12825e] chromedriver!(No symbol) [0x7ff7ae1c2865] chromedriver!(No symbol) [0x7ff7ae1bd1d4] chromedriver!(No symbol) [0x7ff7ae1bd364] chromedriver!(No symbol) [0x7ff7ae1a644c] KERNEL32!BaseThreadInitThunk [0x7ffe31ecdda7+17] ntdll!RtlUserThreadStart [0x7ffe3333ee4c+2c] (ด่านที่ติด: ใส่ชื่อลูกค้าสำเร็จ)
A3: 2026-10-30 09:55:23 | B3: PRICE_MISMATCH | C3: 261027PEH06NGG | D3: [SKU: MNL-002451] Order skipped, CP/DC not set for SKU: MNL-002451 (วันที่: 2026-10-27 10:38, ราคาที่ต้องออกบิล: 13952.0) SHOPEE เวลาสั่งซื้อ 2026-10-27 10:38 MNL-002451 MSI Gaming Monitor MAG 272QP QD-OLED X24 - 26.5"/2K/QD-OLED/240Hz/0.03ms/USB Type C (DP+15w)/3Y*3 MNL-002451 ยิงขายขึ้น 14,148.00 บาท ลูกค้าซื้อราคา 13,952.00 บาท ขอวิธีปรับราคาครับ (ด่านที่ติด: ตรวจสอบราคาและจำนวนสำเร็จ)
A4: 2026-10-30 09:56:21 | B4: PRICE_MISMATCH | C4: 261027PFYSDBP3 | D4: [SKU: MNL-002451] Order skipped, CP/DC not set for SKU: MNL-002451 (วันที่: 2026-10-27 11:04, ราคาที่ต้องออกบิล: 13952.0) SHOPEE เวลาสั่งซื้อ 2026-10-27 11:04 MNL-002451 MSI Gaming Monitor MAG 272QP QD-OLED X24 - 26.5"/2K/QD-OLED/240Hz/0.03ms/USB Type C (DP+15w)/3Y*3 MNL-002451 ยิงขายขึ้น 14,148.00 บาท ลูกค้าซื้อราคา 13,952.00 บาท ขอวิธีปรับราคาครับ (ด่านที่ติด: ตรวจสอบราคาและจำนวนสำเร็จ)
A5: 2026-10-30 09:58:14 | B5: PRICE_MISMATCH | C5: 261027PMWG9H8V | D5: [SKU: MNL-002376] Order skipped, CP/DC not set for SKU: MNL-002376 (วันที่: 2026-10-27 12:32, ราคาที่ต้องออกบิล: 3282.0) SHOPEE เวลาสั่งซื้อ 2026-10-27 12:32 MNL-002376 ASUS Eye Care Gaming Monitor VA279HG - 27"/IPS/120Hz/1ms/Adaptive-Sync/3Y*3 MNL-002376 ยิงขายขึ้น 3,346.00 บาท ลูกค้าซื้อราคา 3,282.00 บาท ขอวิธีปรับราคาครับ (ด่านที่ติด: ตรวจสอบราคาและจำนวนสำเร็จ)
A6: 2026-10-30 10:00:41 | B6: PRICE_MISMATCH | C6: 261027PTRAWKNS | D6: [SKU: MNL-002381] Order skipped, CP/DC not set for SKU: MNL-002381 (วันที่: 2026-10-27 14:17, ราคาที่ต้องออกบิล: 4749.0) SHOPEE เวลาสั่งซื้อ 2026-10-27 14:17 MNL-002381 ACER Gaming Monitor XF273U X1wmiiprx - 27"/IPS/2K/200Hz/0.5ms/3Y MNL-002381 ยิงขายขึ้น 5,199.00 บาท ลูกค้าซื้อราคา 4,749.00 บาท ขอวิธีปรับราคาครับ (ด่านที่ติด: ตรวจสอบราคาและจำนวนสำเร็จ)
A7: 2026-10-30 10:02:47 | B7: PRICE_MISMATCH | C7: 261027Q3TMJP1Y | D7: [SKU: MNL-002381] Order skipped, CP/DC not set for SKU: MNL-002381 (วันที่: 2026-10-27 16:59, ราคาที่ต้องออกบิล: 4749.0) SHOPEE เวลาสั่งซื้อ 2026-10-27 16:59 MNL-002381 ACER Gaming Monitor XF273U X1wmiiprx - 27"/IPS/2K/200Hz/0.5ms/3Y MNL-002381 ยิงขายขึ้น 5,199.00 บาท ลูกค้าซื้อราคา 4,749.00 บาท ขอวิธีปรับราคาครับ (ด่านที่ติด: ตรวจสอบราคาและจำนวนสำเร็จ)
A8: 2026-10-30 10:03:10 | B8: PRICE_MISMATCH | C8: 261027Q56P5G0N | D8: [SKU: MNL-002381] Order skipped, CP/DC not set for SKU: MNL-002381 (วันที่: 2026-10-27 17:24, ราคาที่ต้องออกบิล: 4749.0) SHOPEE เวลาสั่งซื้อ 2026-10-27 17:24 MNL-002381 ACER Gaming Monitor XF273U X1wmiiprx - 27"/IPS/2K/200Hz/0.5ms/3Y MNL-002381 ยิงขายขึ้น 5,199.00 บาท ลูกค้าซื้อราคา 4,749.00 บาท ขอวิธีปรับราคาครับ (ด่านที่ติด: ตรวจสอบราคาและจำนวนสำเร็จ)
A9: 2026-10-30 10:03:50 | B9: PRICE_MISMATCH | C9: 261027Q6WD3704 | D9: [SKU: MNL-002381] Order skipped, CP/DC not set for SKU: MNL-002381 (วันที่: 2026-10-27 17:55, ราคาที่ต้องออกบิล: 4749.0) SHOPEE เวลาสั่งซื้อ 2026-10-27 17:55 MNL-002381 ACER Gaming Monitor XF273U X1wmiiprx - 27"/IPS/2K/200Hz/0.5ms/3Y MNL-002381 ยิงขายขึ้น 5,199.00 บาท ลูกค้าซื้อราคา 4,749.00 บาท ขอวิธีปรับราคาครับ (ด่านที่ติด: ตรวจสอบราคาและจำนวนสำเร็จ)
A10: 2026-10-30 10:04:17 | B10: PRICE_MISMATCH | C10: 261027Q70M25T5 | D10: [SKU: MNL-002381] Order skipped, CP/DC not set for SKU: MNL-002381 (วันที่: 2026-10-27 17:56, ราคาที่ต้องออกบิล: 4749.0) SHOPEE เวลาสั่งซื้อ 2026-10-27 17:56 MNL-002381 ACER Gaming Monitor XF273U X1wmiiprx - 27"/IPS/2K/200Hz/0.5ms/3Y MNL-002381 ยิงขายขึ้น 5,199.00 บาท ลูกค้าซื้อราคา 4,749.00 บาท ขอวิธีปรับราคาครับ (ด่านที่ติด: ตรวจสอบราคาและจำนวนสำเร็จ)
A11: 2026-10-30 10:09:03 | B11: PRICE_MISMATCH | C11: 261027QMYM7R7G | D11: [SKU: PR5-000658] Order skipped, CP/DC not set for SKU: PR5-000658 (วันที่: 2026-10-27 22:06, ราคาที่ต้องออกบิล: 3379.0) SHOPEE เวลาสั่งซื้อ 2026-10-27 22:06 PR5-000658 BROTHER DCP-T230 ปริ้นเตอร์ (PR5-000658) ยิงขายขึ้น 4,290.00 บาท ลูกค้าซื้อราคา 3,379.00 บาท ขอวิธีปรับราคาครับ 💡 [ระบบคำนวณแนะนำ] พบคูปองบน SMCO ที่ลดแล้วได้ราคา 3,379.00 บาท พอดีเป๊ะ: • แนะนำ: 'CP2610210013' (ส่วนลด 911.00 บาท) • บันทึกใส่คอลัมน์ 'suggested_cp' ใน cp_data.xlsx เรียบร้อยแล้ว (เปิดตรวจสอบและคัดลอกได้) (ด่านที่ติด: ตรวจสอบราคาและจำนวนสำเร็จ)
A12: 2026-10-30 10:10:21 | B12: PRICE_MISMATCH | C12: 261028QXBE7JJP | D12: [SKU: MNL-002381] Order skipped, CP/DC not set for SKU: MNL-002381 (วันที่: 2026-10-28 00:54, ราคาที่ต้องออกบิล: 4750.0) SHOPEE เวลาสั่งซื้อ 2026-10-28 00:54 MNL-002381 ACER Gaming Monitor XF273U X1wmiiprx - 27"/IPS/2K/200Hz/0.5ms/3Y MNL-002381 ยิงขายขึ้น 5,199.00 บาท ลูกค้าซื้อราคา 4,750.00 บาท ขอวิธีปรับราคาครับ (ด่านที่ติด: ตรวจสอบราคาและจำนวนสำเร็จ)
... A112: 2026-10-30 17:42:59 | B112: PRICE_MISMATCH | C112: 261029UJHB0EXR | D112: [SKU: MNL-002168] Order skipped, CP/DC not set for SKU: MNL-002168 (วันที่: 2026-10-29 11:33, ราคาที่ต้องออกบิล: 25867.0) SHOPEE เวลาสั่งซื้อ 2026-10-29 11:33 MNL-002168 SAMSUNG Odyssey G85SD Curved Gaming Monitor LS34DG850SEXXT - 34"/2K/OLED/175Hz/3Y*3 MNL-002168 ยิงขายขึ้น 29,267.00 บาท ลูกค้าซื้อราคา 25,867.00 บาท ขอวิธีปรับราคาครับ 💡 [ระบบคำนวณแนะนำ] พบคูปองบน SMCO ที่ลดแล้วได้ราคา 25,867.00 บาท พอดีเป๊ะ: • คูปองเริ่มต้นที่ติดมากับสินค้า: 'CP2609280033' • คูปองที่ต้องเลือกเพิ่ม: 'CP2609290087' • รหัสรวมที่แนะนำ: 'CP2609280033 CP2609290087' (ส่วนลด 3,400.00 บาท) • บันทึกใส่คอลัมน์ 'suggested_cp' ใน cp_data.xlsx เรียบร้อยแล้ว (เปิดตรวจสอบและคัดลอกได้) (ด่านที่ติด: ตรวจสอบราคาและจำนวนสำเร็จ)

Sheet Price_Mismatch_Summary
A1: sku_pattern | B1: expected_price | C1: remaining_failed_count
A2: MNL-002358 | B2: 2199 | C2: =COUNTIFS(Processed_Logs!G:G, "Failed", Processed_Logs!H:H, "PRICE_MISMATCH", Processed_Logs!I:I, "*[SKU: " & A2 & "]*", Processed_Logs!E:E, B2)
A3: MNL-002435 | B3: 2792 | C3: =COUNTIFS(Processed_Logs!G:G, "Failed", Processed_Logs!H:H, "PRICE_MISMATCH", Processed_Logs!I:I, "*[SKU: " & A3 & "]*", Processed_Logs!E:E, B3)
A4: MNL-002381 | B4: 4749 | C4: =COUNTIFS(Processed_Logs!G:G, "Failed", Processed_Logs!H:H, "PRICE_MISMATCH", Processed_Logs!I:I, "*[SKU: " & A4 & "]*", Processed_Logs!E:E, B4)
A5: MNL-002381 | B5: 4750 | C5: =COUNTIFS(Processed_Logs!G:G, "Failed", Processed_Logs!H:H, "PRICE_MISMATCH", Processed_Logs!I:I, "*[SKU: " & A5 & "]*", Processed_Logs!E:E, B5)
A6: MNL-002577 | B6: 9450 | C6: =COUNTIFS(Processed_Logs!G:G, "Failed", Processed_Logs!H:H, "PRICE_MISMATCH", Processed_Logs!I:I, "*[SKU: " & A6 & "]*", Processed_Logs!E:E, B6)
A7: MNL-002376 | B7: 3282 | C7: =COUNTIFS(Processed_Logs!G:G, "Failed", Processed_Logs!H:H, "PRICE_MISMATCH", Processed_Logs!I:I, "*[SKU: " & A7 & "]*", Processed_Logs!E:E, B7)
A8: MNL-002535 | B8: 4005 | C8: =COUNTIFS(Processed_Logs!G:G, "Failed", Processed_Logs!H:H, "PRICE_MISMATCH", Processed_Logs!I:I, "*[SKU: " & A8 & "]*", Processed_Logs!E:E, B8)
A9: MNL-002451 | B9: 13952 | C9: =COUNTIFS(Processed_Logs!G:G, "Failed", Processed_Logs!H:H, "PRICE_MISMATCH", Processed_Logs!I:I, "*[SKU: " & A9 & "]*", Processed_Logs!E:E, B9)
A10: COA-002069 | B10: 0 | C10: =COUNTIFS(Processed_Logs!G:G, "Failed", Processed_Logs!H:H, "PRICE_MISMATCH", Processed_Logs!I:I, "*[SKU: " & A10 & "]*", Processed_Logs!E:E, B10)
A11: PR5-000658 | B11: 3379 | C11: =COUNTIFS(Processed_Logs!G:G, "Failed", Processed_Logs!H:H, "PRICE_MISMATCH", Processed_Logs!I:I, "*[SKU: " & A11 & "]*", Processed_Logs!E:E, B11)
A12: MNL-002475 | B12: 9100 | C12: =COUNTIFS(Processed_Logs!G:G, "Failed", Processed_Logs!H:H, "PRICE_MISMATCH", Processed_Logs!I:I, "*[SKU: " & A12 & "]*", Processed_Logs!E:E, B12)
A13: MNL-002561 | B13: 8582 | C13: =COUNTIFS(Processed_Logs!G:G, "Failed", Processed_Logs!H:H, "PRICE_MISMATCH", Processed_Logs!I:I, "*[SKU: " & A13 & "]*", Processed_Logs!E:E, B13)
... A24: PW1-000651 | B24: 1699 | C24: =COUNTIFS(Processed_Logs!G:G, "Failed", Processed_Logs!H:H, "PRICE_MISMATCH", Processed_Logs!I:I, "*[SKU: " & A24 & "]*", Processed_Logs!E:E, B24)

Sheet Sheet6
